Workbook

Sheet Comparison
A1: R350 tribe member comparison - 2026-10-27 vs 2026-10-31 (ELAPSED 4 days)
A2: D1 198 stored rows | D2 195 rows (game UI NOT GIVEN) | Pass 1 186 | Pass 2 6 | Pass 3 0 | departures 6 | D2-only 3 | KP_CEIL 16.3010% (max of 186-pair control group x 1.1)
A4: # | B4: ID | C4: Name (D1) | D4: Name (D2) | E4: Note | F4: Power D1 | G4: Kill Pts D1 | H4: Act Pts D1 | I4: Power D2 | J4: Kill Pts D2 | K4: Act Pts D2 | L4: Δ Power | M4: Δ Power % | N4: Δ Kill Pts | O4: Δ Kill Pts % | P4: Δ Act Pts
A5: 1 | B5: R350-0001 | C5: Чугуш | D5: Чугуш | E5: Exact name match (Pass 1) via alias screen name "Чугуш" | F5: 848005443 | G5: 44538316209 | H5: 14583899 | I5: 837301257 | J5: 47163075927 | K5: 0 | L5: =I5-F5 | M5: =IFERROR((I5-F5)/F5,"") | N5: =J5-G5 | O5: =IFERROR((J5-G5)/G5,"") | P5: =K5-H5
A6: 2 | B6: R350-0002 | C6: Единств | D6: Единств | E6: Exact name match (Pass 1) via canonical | F6: 718323221 | G6: 75013750172 | H6: 108666078 | I6: 716691410 | J6: 81945369415 | K6: 109285678 | L6: =I6-F6 | M6: =IFERROR((I6-F6)/F6,"") | N6: =J6-G6 | O6: =IFERROR((J6-G6)/G6,"") | P6: =K6-H6
A7: 3 | B7: R350-0004 | C7: Timmeee | D7: Timmeee | E7: Exact name match (Pass 1) via canonical | F7: 384785387 | G7: 36567206144 | H7: 340400 | I7: 385119915 | J7: 40536645453 | K7: 203900 | L7: =I7-F7 | M7: =IFERROR((I7-F7)/F7,"") | N7: =J7-G7 | O7: =IFERROR((J7-G7)/G7,"") | P7: =K7-H7
A8: 4 | B8: R350-0005 | C8: Asterion ツ | D8: ASTERION | E8: Exact name match (Pass 1) via canonical | F8: 312465422 | G8: 29352192962 | H8: 6826900 | I8: 310280775 | J8: 30890317548 | K8: 329900 | L8: =I8-F8 | M8: =IFERROR((I8-F8)/F8,"") | N8: =J8-G8 | O8: =IFERROR((J8-G8)/G8,"") | P8: =K8-H8
A9: 5 | B9: R350-0250 | C9: FinistBrFalcon | D9: FinistBrFalcon | E9: Exact name match (Pass 1) via canonical | F9: 298464313 | G9: 30117120688 | H9: 8375384 | I9: 297883139 | J9: 33548535880 | K9: 235600 | L9: =I9-F9 | M9: =IFERROR((I9-F9)/F9,"") | N9: =J9-G9 | O9: =IFERROR((J9-G9)/G9,"") | P9: =K9-H9
A10: 6 | B10: R350-0007 | C10: Lastangel001 | D10: Lastangel001 | E10: Exact name match (Pass 1) via canonical | F10: 288362799 | G10: 21663422094 | H10: 10230893 | I10: 256056577 | J10: 22906829035 | K10: 33000 | L10: =I10-F10 | M10: =IFERROR((I10-F10)/F10,"") | N10: =J10-G10 | O10: =IFERROR((J10-G10)/G10,"") | P10: =K10-H10
A11: 7 | B11: R350-0008 | C11: CRx StalinIV | D11: CRx StalinIV | E11: Exact name match (Pass 1) via canonical | F11: 279403460 | G11: 11857465931 | H11: 15784264 | I11: 276670394 | J11: 12652779991 | K11: 170000 | L11: =I11-F11 | M11: =IFERROR((I11-F11)/F11,"") | N11: =J11-G11 | O11: =IFERROR((J11-G11)/G11,"") | P11: =K11-H11
A12: 8 | B12: R350-0014 | C12: Shebeastinem | D12: Shebeastinem | E12: Exact name match (Pass 1) via canonical | F12: 271909156 | G12: 45548248984 | H12: 736800 | I12: 275298989 | J12: 48145823364 | K12: 400 | L12: =I12-F12 | M12: =IFERROR((I12-F12)/F12,"") | N12: =J12-G12 | O12: =IFERROR((J12-G12)/G12,"") | P12: =K12-H12
A13: 9 | B13: R350-0006 | C13: skywraith | D13: skywraith | E13: Exact name match (Pass 1) via canonical | F13: 269883465 | G13: 9109835335 | H13: 41531657 | I13: 255337357 | J13: 9266715671 | K13: 11800 | L13: =I13-F13 | M13: =IFERROR((I13-F13)/F13,"") | N13: =J13-G13 | O13: =IFERROR((J13-G13)/G13,"") | P13: =K13-H13
A14: 10 | B14: R350-0017 | C14: Colt Canon | D14: Colt Canon | E14: Exact name match (Pass 1) via canonical | F14: 250140205 | G14: 13600321862 | H14: 20496560 | I14: 247056002 | J14: 14359276654 | K14: 521463 | L14: =I14-F14 | M14: =IFERROR((I14-F14)/F14,"") | N14: =J14-G14 | O14: =IFERROR((J14-G14)/G14,"") | P14: =K14-H14
A15: 11 | B15: R350-0009 | C15: Nordic Oak | D15: Nordic Oak | E15: Exact name match (Pass 1) via canonical | F15: 248443422 | G15: 15249149365 | H15: 33464067 | I15: 242251788 | J15: 15768777934 | K15: 230600 | L15: =I15-F15 | M15: =IFERROR((I15-F15)/F15,"") | N15: =J15-G15 | O15: =IFERROR((J15-G15)/G15,"") | P15: =K15-H15
A16: 12 | B16: R350-0015 | C16: TikiCat | D16: TikiCat | E16: Exact name match (Pass 1) via canonical | F16: 241226970 | G16: 9707007674 | H16: 20952122 | I16: 227329036 | J16: 10085298941 | K16: 54000 | L16: =I16-F16 | M16: =IFERROR((I16-F16)/F16,"") | N16: =J16-G16 | O16: =IFERROR((J16-G16)/G16,"") | P16: =K16-H16
... A199: 195 | B199: R350-0142 | C199: Simona | D199: Simona | E199: PRESENT per Chow (NOT a departure) - not captured in 31/10 video; current stats from Chow screenshot: Power 158,733,482 / KP 6,931,115,332, nickname llllllllllll; Act 0 (Chow 31/10). [Video evidence was: Only in D1 - evidence A: Power falls between D2 rows 146 nirr (156,099,252) and 147 RAIJIN (154,939,826), observed adjacent in the same panel: YES] | F199: 155482293 | G199: 6389446860 | H199: 13517000 | I199: 158733482 | J199: 6931115332 | K199: 0 | L199: =I199-F199 | M199: =IFERROR((I199-F199)/F199,"") | N199: =J199-G199 | O199: =IFERROR((J199-G199)/G199,"") | P199: =K199-H199
A200: 196 | B200: R350-0189 | C200: Деонисс | E200: Only in D1 - evidence A: Power falls between D2 rows 184 Enem (132,715,306) and 185 Tyr Olafsson (131,846,633), observed adjacent in the same panel: YES | F200: 132682327 | G200: 856282541 | H200: 67824514
A201: 197 | B201: R350-0193 | C201: Leader392837282 | D201: Leader392837282 | E201: PRESENT per Chow (NOT a departure) - not captured in 31/10 video; current stats from Chow 31/10: Power 115,342,329 / KP 1,302,918,192 / Act 0. [Video evidence was: Only in D1 - evidence A: Power falls between D2 rows 190 Macabeyi (125,972,391) and 191 viking 22 (122,771,308), observed adjacent in the same panel: YES] | F201: 123821196 | G201: 1217214211 | H201: 91334778 | I201: 115342329 | J201: 1302918192 | K201: 0 | L201: =I201-F201 | M201: =IFERROR((I201-F201)/F201,"") | N201: =J201-G201 | O201: =IFERROR((J201-G201)/G201,"") | P201: =K201-H201
A202: 198 | B202: R350-0217 | C202: kira21 | D202: kira is sleepy | E202: Renamed per Chow (NOT a departure, NOT a newcomer): kira21 = kira is sleepy; canonical name kept kira21, screen name kira is sleepy to aliases. Power -22.09% (KVK fighting), KP +3.48%. [Video evidence was: Only in D1 - evidence A: Power falls between D2 rows 191 viking 22 (122,771,308) and 192 TarunPy (119,730,710), observed adjacent in the same panel: YES - explained by rename + Power drop to D2 row 194.] | F202: 120776143 | G202: 454360373 | H202: 841000 | I202: 94094747 | J202: 470155550 | K202: 1433100 | L202: =I202-F202 | M202: =IFERROR((I202-F202)/F202,"") | N202: =J202-G202 | O202: =IFERROR((J202-G202)/G202,"") | P202: =K202-H202
A203: 199 | D203: Grigoryan | E203: REJOIN CONFIRMED per Chow: R350-0254 Grigoryan (absent since 2026-10-26, returned 31/10; dKP +1.05%, dPower -0.61%). Original candidates were: R350-0254 Grigoryan 0.209%/day; R350-0019 Kral38 1.523%/day; R350-0040 Pisos 3.306%/day; R350-0177 Piyush 5.828%/day; R350-0134 darkhof 9.535%/day. | I203: 207688462 | J203: 16901319156 | K203: 0
A204: 200 | D204: ТОНИГАН | E204: REJOIN CONFIRMED per Chow: R350-0163 TONIGAN (absent since 2026-09-06, returned 31/10; dKP +2.95%, dPower +17.31%). Original candidates were: R350-0163 TONIGAN 0.054%/day; R350-0139 VotTakVot 0.169%/day; R350-0166 RoryWest 0.175%/day; R350-0192 kwitchypoo 0.257%/day; R350-0168 Nana 0.266%/day. | I204: 180271383 | J204: 1325607869 | K204: 74400
A205: 201 | D205: kira is sleepy | E205: MERGED into R350-0217 kira21 per Chow (same person) - see row 202; do not count separately.
C206: TOTAL | F206: =SUM(F5:F205) | G206: =SUM(G5:G205) | H206: =SUM(H5:H205) | I206: =SUM(I5:I205) | J206: =SUM(J5:J205) | K206: =SUM(K5:K205)

Sheet Summary
A1: Summary - 2026-10-27 vs 2026-10-31
A3: Metric | B3: D1 (2026-10-27) | C3: D2 (2026-10-31) | D3: Δ | E3: Δ %
A4: Members | B4: =COUNT(Comparison!F5:F205) | C4: =COUNT(Comparison!I5:I205) | D4: =C4-B4 | E4: =IFERROR((C4-B4)/B4,"")
A5: Tribe Power | B5: =Comparison!F206 | C5: =Comparison!I206 | D5: =C5-B5 | E5: =IFERROR((C5-B5)/B5,"")
A6: Tribe Kill Points | B6: =Comparison!G206 | C6: =Comparison!J206 | D6: =C6-B6 | E6: =IFERROR((C6-B6)/B6,"")
A7: Tribe Activity Points | B7: =Comparison!H206 | C7: =Comparison!K206 | D7: =C7-B7 | E7: =IFERROR((C7-B7)/B7,"")
A10: Table 1 - Top 20 Kill Points increase
A11: # | B11: Member Name | C11: Kill Pts (D1) | D11: Kill Pts (D2) | E11: Δ Kill Pts | F11: Note
A12: 1 | B12: Единств | C12: 75013750172 | D12: 81945369415 | E12: 6931619243 | F12: R350-0002
A13: 2 | B13: MONSTER DONG | C13: 33381976573 | D13: 37800476342 | E13: 4418499769 | F13: R350-0027
A14: 3 | B14: Timmeee | C14: 36567206144 | D14: 40536645453 | E14: 3969439309 | F14: R350-0004
A15: 4 | B15: FinistBrFalcon | C15: 30117120688 | D15: 33548535880 | E15: 3431415192 | F15: R350-0250
A16: 5 | B16: Чугуш | C16: 44538316209 | D16: 47163075927 | E16: 2624759718 | F16: R350-0001
A17: 6 | B17: Shebeastinem | C17: 45548248984 | D17: 48145823364 | E17: 2597574380 | F17: R350-0014
A18: 7 | B18: ASTERION | C18: 29352192962 | D18: 30890317548 | E18: 1538124586 | F18: R350-0005
A19: 8 | B19: Lastangel001 | C19: 21663422094 | D19: 22906829035 | E19: 1243406941 | F19: R350-0007
A20: 9 | B20: ZVYAG | C20: 18657935967 | D20: 19719179441 | E20: 1061243474 | F20: R350-0018
A21: 10 | B21: Cookies | C21: 22203386027 | D21: 23092079163 | E21: 888693136 | F21: R350-0013
A22: 11 | B22: Barb | C22: 17412187389 | D22: 18225667018 | E22: 813479629 | F22: R350-0093
A23: 12 | B23: llllllllll | C23: 9398379123 | D23: 10206524626 | E23: 808145503 | F23: R350-0044
... A31: 20 | B31: DANIEL SHEHU | C31: 23063477575 | D31: 23722503553 | E31: 659025978 | F31: R350-0021
A33: Table 2 - Top 20 Power drop
A34: # | B34: Member Name | C34: Power D1 | D34: Power D2 | E34: Δ Power (abs) | F34: Δ Power % | G34: Kill Pts D2 | H34: Note
A35: 1 | B35: ТагилРу | C35: 173000563 | D35: 119730710 | E35: -53269853 | F35: -0.30791722 | G35: 1242764131 | H35: R350-0133
A36: 2 | B36: Lastangel001 | C36: 288362799 | D36: 256056577 | E36: -32306222 | F36: -0.11203325 | G36: 22906829035 | H36: R350-0007
A37: 3 | B37: Doc7Ragnar | C37: 171549030 | D37: 141180397 | E37: -30368633 | F37: -0.17702597 | G37: 1031703025 | H37: R350-0123
A38: 4 | B38: Be3yhunk | C38: 230487441 | D38: 200385940 | E38: -30101501 | F38: -0.13059931 | G38: 4856437113 | H38: R350-0034
A39: 5 | B39: Belka | C39: 220586764 | D39: 195100845 | E39: -25485919 | F39: -0.11553694 | G39: 12027724734 | H39: R350-0020
A40: 6 | B40: Frozen | C40: 239663468 | D40: 215247797 | E40: -24415671 | F40: -0.10187481 | G40: 2522403021 | H40: R350-0030
A41: 7 | B41: zapekanka | C41: 182785268 | D41: 161558801 | E41: -21226467 | F41: -0.11612789 | G41: 3096563990 | H41: R350-0068
A42: 8 | B42: Phá Quân | C42: 227224634 | D42: 207057748 | E42: -20166886 | F42: -0.088753079 | G42: 2223690599 | H42: R350-0032
A43: 9 | B43: Laland | C43: 172101968 | D43: 152498071 | E43: -19603897 | F43: -0.11390862 | G43: 1218747594 | H43: R350-0128
A44: 10 | B44: Phúc XO | C44: 203382515 | D44: 184077486 | E44: -19305029 | F44: -0.094919807 | G44: 2787202726 | H44: R350-0037
A45: 11 | B45: Enem | C45: 151559726 | D45: 132715306 | E45: -18844420 | F45: -0.12433659 | G45: 3855543662 | H45: R350-0160
A46: 12 | B46: Macabeyi | C46: 144507847 | D46: 125972391 | E46: -18535456 | F46: -0.12826609 | G46: 4226985271 | H46: R350-0144
... A54: 20 | B54: Kenvin Tai | C54: 181503223 | D54: 169580009 | E54: -11923214 | F54: -0.065691473 | G54: 1209657609 | H54: R350-0154
A56: Table 3 - renamed / ambiguous / override (for Ha to confirm)
A57: # | B57: ID | C57: Screen D1 | D57: Screen D2 | E57: Rank D1→D2 | F57: Δ Power % | G57: Δ KP % | H57: Act D1→D2 | I57: mtype | J57: Evidence | K57: competitors | L57: status
A58: 1 | B58: R350-0276 | C58: contactmeboys | D58: SosiPisoS | E58: 56→40 | F58: 0.021258733 | G58: 0.012181381 | H58: 5,828,806→6,687,106 | I58: renamed | J58: renamed (Pass 2): dPower +2.08%, dKP +1.2181%, name similarity 0.27, competitors 1, neighbourhood_size 151; UNIQUENESS: FAILED | K58: 1 | L58: unresolved
A59: 2 | B59: R350-0044 | C59: KatalonEc | D59: llllllllll | E59: 81→72 | F59: 0.014871305 | G59: 0.085987753 | H59: 925,741→487,200 | I59: ambiguous | J59: ambiguous (Pass 2): dPower +1.47%, dKP +8.5988%, name similarity 0.11, competitors 4, neighbourhood_size 151; UNIQUENESS: FAILED | K59: 4 | L59: unresolved
...

Sheet Legend
A1: Legend and method - comparison 2026-10-27 vs 2026-10-31
A3: COLOURS
A4: white / EBF3FB alternating = exact name match (Pass 1)
A5: FFF2CC = renamed / ambiguous / override pair
A6: FCE4D6 = only in D1 (left the tribe)
A7: E2EFDA = only in D2 (new / rejoin / excluded)
A9: METHOD (VR_member_comparison_v8, script vr_compare.py)
A10: Pass 1 exact name (canonical + alias, fkey + skey), no rank window: 186 pairs
A11: Pass 2 Hungarian, KP_CEIL 16.3010%, |dPower|<=20%, RANK_WIN 49: 6 pairs
A12: Pass 3 override (no rank window, dKP<=5%, dPower<=20%, dAct<=25%, score<1.0): 0 pairs
A13: Control group: n=186, min 0.0000%, median 2.9323%, p90 7.5009%, max 14.8191% -> KP_CEIL 16.3010% (max of 186-pair control group x 1.1)
A14: Sensitivity: Pass 2 re-run at KP_CEIL x1.25 and x2.5; a pair that changes partner is UNSTABLE -> unresolved
... A21: IDENTITY RULES: Kill Points never decrease; metrics identify, names do not; stroke count is not identity.
